Workbook

Sheet 통합 체크리스트
A1: ☐ | B1: 임무단계 | C1: 단계명 | D1: 출처 | E1: ID | F1: 절차명(KO) | G1: 절차명(EN) | H1: 트리거 | I1: 한 줄 체크리스트 (DCS 조작) | J1: DCS 적용성 | K1: BOLDFACE | L1: 원문 p.
A2: ■ P0 임무계획 / DTC 준비 (Mission Planning / DTC) — 비행 전 임무계획 단계. DTC 데이터 준비, 무장·퓨즈 선정, TOS 계획.
A3: ☐ | B3: P0 | C3: 임무계획 / DTC 준비 | D3: Dash-1 | E3: R-03 | F3: 속도/고도, 연료 예비량, 기상, 급유 전달률 기준 | G3: Airspeeds, Altitudes, Fuel Reserve, Weather, Refueling Transfer Rate | H3: 임무계획(연료계획/급유 트랙 설정) 시; 급유 트랙 진입 시 속도·고도 기준 확인 | I3: 탱커 고도/속도 브리핑 → BNGO 30분 예비 설정 + HUD 표시 → 기상 최저치 확인 → 전달률 기반 접촉시간 계획 → CRUS TOS로 ARCT 관리 | J3: 부분적용 | L3: 8-1
A4: ☐ | B4: P0 | C4: 임무계획 / DTC 준비 | D4: Dash-1 | E4: R-22 | F4: 랑데부 고도블록 배정 | G4: Rendezvous Altitude Block | H4: 급유 트랙 고도 블록 계획 시; ARIP 이탈 후 랑데부 고도 진입 시 | I4: 탱커 트랙 고도 확인 → 전투기 랑데부 고도 = 탱커 -1000ft → 탱커 지시 고도 확인 → ALT HOLD로 유지 → 시각접촉 후 합류 | J4: 부분적용 | L4: 8-20
A5: ☐ | B5: P0 | C5: 임무계획 / DTC 준비 | D5: Dash-34 | E5: MP-01 | F5: 자동 초기화(DTE) 절차 | G5: Automated Initialization (DTE) Procedures | H5: 항전 전원(MMC/MFD/UFC) 인가 및 INS 정렬 시작 후, C&I 스위치를 UFC로 전환하기 전·후의 시동 후 셋업 시점 | I5: DTC 데이터 준비 확인 → MFD Main Menu → DTE → LOAD(전체) 또는 항목별 OSB → 강조 표시 확인 → DED에서 값 검증 | J5: 부분적용 | L5: 1-266
A6: ☐ | B6: P0 | C6: 임무계획 / DTC 준비 | D6: Dash-34 | E6: SUP-01 | F6: Section III 보충 자료 (퓨즈 무장시간·안전이탈거리 차트) | G6: Section III Supplementary Data (Fuze Arming Time / Safe Escape Charts) | H6: 임무계획 시 투하 고도/속도/강하각·퓨즈 설정 선정 시 | I6: 차트로 투하 파라미터 결정 → SMS CNTL AD/BA·HoF 입력 → 퓨즈/간격/펄스 → PUAC 준수 → 투하 후 이탈 기동 | J6: 부분적용 | L6: 3-1
A7: ■ P1 조종석 진입 전 · 외부점검 (Preflight Inspection) — 항공기 외부/무장 점검(walkaround). DCS에서는 미션에디터 로드아웃·SMS INV로 대체.
A8: ☐ | B8: P1 | C8: 조종석 진입 전 · 외부점검 | D8: Dash-1 | E8: N-37 | F8: 보충 절차 - 참조 항목(외부점검·위험구역·선회반경·G-Suit 호스경로·생소기지 절차) | G8: Supplemental Procedures - Reference Items (Exterior Inspection, Danger Areas, Turning Radius, G-Suit Hose Routing, Strange Field) | H8: 비행 전 외부점검 시 / 지상 이동·주기 계획 시(참조) | I8: F2 외부 시점 워크어라운드(형상·탑재·손상) → SMS/INV 탑재 확인 → (위험구역·G-Suit·생소기지 생략) | J8: 부분적용 | L8: 2-32~2-42
A9: ☐ | B9: P1 | C9: 조종석 진입 전 · 외부점검 | D9: Dash-1 | E9: W-07 | F9: 저온기상 운용 — 조종석 탑승 전 | G9: Cold Weather Operation - Before Entering Cockpit | H9: 저온·강수·결빙 기상에서 비행 전 외부점검 시(기온 7°C 이하 + 습기/강수/노점 근접) | I9: (미구현) 저온 외부점검 — 얼음/눈 제거는 DCS 미모델링 | J9: 미구현 | L9: 7-5
A10: ☐ | B10: P1 | C10: 조종석 진입 전 · 외부점검 | D10: Dash-1 | E10: W-15 | F10: 고온기상 및 사막 지상운용 | G10: Hot Weather and Desert Ground Operation | H10: 사막/고온다습 환경에서 비행 전 외부점검 또는 비행 후 주기 시 | I10: (미구현) 사막/고온 지상운용 — 캐노피 폐쇄만 가능 | J10: 미구현 | L10: 7-7
A11: ☐ | B11: P1 | C11: 조종석 진입 전 · 외부점검 | D11: Dash-34 | E11: PF-02 | F11: M61A1 기관포 점검 (실탄/공포) | G11: M61A1 Gun Inspection (Hot Gun / Cold Gun) | H11: 조종석 탑승 전 외부 점검(실기) / DCS: 미션 에디터 로드아웃 설정 시 및 시동 후 SMS INV 페이지 확인 시 | I11: (미구현) 미션 에디터 건 탄약 확인 → SMS INV 건 잔량 확인 → 필요 시 지상요원 재무장 | J11: 미구현 | L11: 1-534
A12: ☐ | B12: P1 | C12: 조종석 진입 전 · 외부점검 | D12: Dash-34 | E12: PF-03 | F12: 채프/플레어 디스펜서 점검 | G12: Chaff/Flare Dispenser Inspection | H12: 조종석 탑승 전 외부 점검(실기) / DCS: 미션 에디터 채프·플레어 수량 설정 시 및 CMDS 셋업 시 | I12: (미구현) 미션 에디터/지상요원 채프·플레어 수량 → CMDS CH/FL ON → 수량 표시 확인 | J12: 미구현 | L12: 1-536
A13: ☐ | B13: P1 | C13: 조종석 진입 전 · 외부점검 | D13: Dash-34 | E13: PF-04 | F13: 공대공 미사일 점검 (AIM-9 계열, AIM-120) | G13: Air-to-Air Missiles Inspection (AIM-9N/P/P-4/P-5, AIM-9L/M/S, AIM-120B) | H13: 조종석 탑승 전 외부 점검(실기) / DCS: 미션 에디터 로드아웃 설정 시 및 시동 후 SMS INV 확인 시 | I13: (미구현) 미션 에디터 A-A 로드아웃 → SMS INV 확인 → A-A SMS WARM/COOL 확인 | J13: 미구현 | L13: 1-537
A14: ☐ | B14: P1 | C14: 조종석 진입 전 · 외부점검 | D14: Dash-34 | E14: PF-05 | F14: 현수 장비 점검 (파일런, 랙, 런처) | G14: Suspension Equipment Inspection (Pylons, Racks, Launchers) | H14: 조종석 탑승 전 외부 점검(실기) / DCS: 미션 에디터 로드아웃 설정 시 | I14: (미구현) 미션 에디터 스테이션 랙/런처 확인 → SMS INV 약어 확인 | J14: 미구현 | L14: 1-542
A15: ☐ | B15: P1 | C15: 조종석 진입 전 · 외부점검 | D15: Dash-34 | E15: PF-06 | F15: 기타 스토어 점검 (연료탱크, ECM 포드, NVP, 타게팅 포드) | G15: Miscellaneous Stores Inspection (Fuel Tanks, ECM Pods, NVP, Targeting Pod) | H15: 조종석 탑승 전 외부 점검(실기) / DCS: 미션 에디터 로드아웃 설정 시 및 시동 후 TGP/ECM 전원 인가 시 | I15: (미구현) 로드아웃 확인 → 외부탱크 연료량(EXT 선택) → ECM 패널 → TGP 전원/비디오 확인 | J15: 미구현 | L15: 1-550
A16: ☐ | B16: P1 | C16: 조종석 진입 전 · 외부점검 | D16: Dash-34 | E16: PF-07 | F16: 폭탄류 점검 (일반목적탄, 유도폭탄, 클러스터, 관통탄) | G16: Bombs Inspection (General Purpose, Guided, Cluster, Penetrator) | H16: 조종석 탑승 전 외부 점검(실기) / DCS: 미션 에디터 로드아웃 설정 시 및 시동 후 SMS 확인 시 | I16: (미구현) 미션 에디터 폭탄 로드아웃 → SMS INV 확인 → A-G SMS 퓨즈/프로파일 확인 | J16: 미구현 | L16: 1-553
A17: ☐ | B17: P1 | C17: 조종석 진입 전 · 외부점검 | D17: Dash-34 | E17: PF-08 | F17: 신관 점검 (노즈/테일 기계식·전자식 신관) | G17: Fuzes Inspection (Nose/Tail Mechanical and Electronic Fuzes) | H17: 조종석 탑승 전 외부 점검(실기) / DCS: 미션 에디터 무장 옵션 설정 시 및 A-G SMS 프로파일 설정 시 | I17: (미구현) 미션 에디터 신관 옵션 → SMS CNTL AD/BA·HoF/RPM 확인 | J17: 미구현 | L17: 1-562
A18: ☐ | B18: P1 | C18: 조종석 진입 전 · 외부점검 | D18: Dash-34 | E18: PF-09 | F18: 암밍 와이어/랜야드 점검 | G18: Arming Wires/Lanyards Inspection | H18: 조종석 탑승 전 외부 점검(실기) / DCS: A-G SMS 퓨즈 옵션 설정 시 | I18: (미구현) SMS 퓨즈 옵션으로 고/저항력 선택 → 로드아웃 확인 | J18: 미구현 | L18: 1-579
A19: ☐ | B19: P1 | C19: 조종석 진입 전 · 외부점검 | D19: Dash-34 | E19: PF-10 | F19: 로켓 및 공대지 미사일 점검 (AGM-88, AGM-65) | G19: Rockets and Air-to-Ground Missiles Inspection (AGM-88, AGM-65) | H19: 조종석 탑승 전 외부 점검(실기) / DCS: 미션 에디터 로드아웃 설정 시 및 시동 후 SMS INV 확인 시 | I19: (미구현) 미션 에디터 로켓/HARM/MAV 로드아웃 → SMS INV 확인 → (비행 중) MAV PWR·WPN 비디오 확인 | J19: 미구현 | L19: 1-640
... A21: ☐ | B21: P1 | C21: 조종석 진입 전 · 외부점검 | D21: Dash-34 | E21: PF-01 | F21: 내부 점검 (조종석 탑승 전) | G21: Interior Inspection (Prior to Entering Cockpit) | H21: 조종석 탑승 직전(AGTS 견인 표적 세트 장착 임무 시) | I21: (미구현) AGTS 제어반 점검 — DCS 해당 없음 | J21: 미구현 | L21: 1-650
A22: ■ P2 전원 인가 · 시동 전 (Before Engine Start) — 배터리/MAIN PWR, 시동 전 점검.
A23: ☐ | B23: P2 | C23: 전원 인가 · 시동 전 | D23: Dash-1 | E23: N-01 | F23: 조종석 진입 | G23: Cockpit Access | H23: 외부점검 완료 후 조종석 진입 시(DCS: 콜드&다크 램프 스타트 미션 슬롯 진입 시) | I23: 캐노피 OPEN(스파이더 가드 개방 → Canopy 스위치 UP / LCTRL+C) → 착석 상태 확인 | J23: 부분적용 | L23: 2-2
A24: ☐ | B24: P2 | C24: 전원 인가 · 시동 전 | D24: Dash-1 | E24: N-02 | F24: 조종석 진입 전 점검 | G24: Before Entering Cockpit | H24: 조종석 진입 직후, 착석·하네스 체결 전 | I24: 사출레버 SAFE(UP) → MAIN PWR OFF → 오디오 SQL/볼륨 CCW → ALT GEAR IN → ALT FLAPS NORM → GND JETT OFF → HOOK UP → 실내조명 OFF → OXY OFF/100% | J24: 부분적용 | L24: 2-2
A25: ☐ | B25: P2 | C25: 전원 인가 · 시동 전 | D25: Dash-1 | E25: N-03 | F25: 조종석 내부 점검 - 좌측 콘솔 | G25: Cockpit Interior Check - Left Console | H25: 착석·하네스 체결·러더 페달 조절 후, MAIN PWR 인가 전 | I25: PROBE HEAT OFF → FLCS PWR TEST NORM → DBU OFF → ALT FLAPS NORM → LEF AUTO → BIT OFF → TRIM NORM/트림 0 → FUEL MASTER/ENG FEED NORM/AR CLOSE → IFF STBY/C&I BACKUP → EPU NORM/MAIN PWR OFF → AVTR·ECM OFF → COMM1/2 ON·SQL → ENG CONT PRI/JFS OFF → 스로틀 OFF → SPD BRK FWD/DOGFIGHT Center | J25: 부분적용 | L25: 2-3~2-4
A26: ☐ | B26: P2 | C26: 전원 인가 · 시동 전 | D26: Dash-1 | E26: N-04 | F26: 조종석 내부 점검 - 좌측 보조 콘솔 | G26: Cockpit Interior Check - Left Auxiliary Console | H26: 좌측 콘솔 점검(N-03) 완료 직후 | I26: ALT GEAR IN → CMDS 전원 OFF/MODE OFF → RF NORM → LASER ARM OFF → HUD 패널 설정·고도계 QNH → FUEL QTY NORM/EXT TRANS NORM → STORES CONFIG CAT I/III → LDG/TAXI LT OFF → LG DN → GND JETT OFF → BRAKES CHAN 1/PARKING BRAKE → HOOK UP → EHSI 모드 | J26: 부분적용 | L26: 2-4~2-5
A27: ☐ | B27: P2 | C27: 전원 인가 · 시동 전 | D27: Dash-1 | E27: N-05 | F27: 조종석 내부 점검 - 계기판 | G27: Cockpit Interior Check - Instrument Panel | H27: 좌측 보조 콘솔 점검(N-04) 완료 직후 | I27: A/P ROLL ATT HOLD(중앙) → A/P PITCH A/P OFF → MASTER ARM OFF | J27: 적용 | L27: 2-5
A28: ☐ | B28: P2 | C28: 전원 인가 · 시동 전 | D28: Dash-1 | E28: N-06 | F28: 조종석 내부 점검 - 우측 보조 콘솔 | G28: Cockpit Interior Check - Right Auxiliary Console | H28: 계기판 점검(N-05) 완료 직후 | I28: 시계 시각 확인(자동) → (D형 항목 생략) | J28: 부분적용 | L28: 2-5
A29: ☐ | B29: P2 | C29: 전원 인가 · 시동 전 | D29: Dash-1 | E29: N-07 | F29: 조종석 내부 점검 - 우측 콘솔 | G29: Cockpit Interior Check - Right Console | H29: 우측 보조 콘솔 점검(N-06) 완료 직후 | I29: SNSR PWR 4개 OFF → HUD 패널 → ZEROIZE OFF → 실내조명 → VMS ON → TEMP AUTO/AIR SOURCE NORM → AVIONICS PWR 8개 OFF → ANTI ICE AUTO → IFF/UHF ANT NORM → 산소 ON/NORM/압력·유량 확인 | J29: 부분적용 | L29: 2-5~2-6
A30: ☐ | B30: P2 | C30: 전원 인가 · 시동 전 | D30: Dash-1 | E30: N-08 | F30: 조종석 점검 완료 후 확인 | G30: After Cockpit Check Is Complete - Verify | H30: 조종석 내부 점검(N-03~N-07) 완료 후, MAIN PWR BATT 인가 직전 | I30: FUEL MASTER → ENG FEED NORM → EPU NORM → ENG CONT PRI → 스로틀 OFF → LG DN → HOOK UP → MASTER ARM OFF → AIR SOURCE NORM | J30: 적용 | L30: 2-6~2-7
A31: ☐ | B31: P2 | C31: 전원 인가 · 시동 전 | D31: Dash-1 | E31: N-09 | F31: 엔진 시동 전 절차 | G31: Before Starting Engine | H31: 조종석 점검 완료 후, JFS 시동 직전 | I31: MAIN PWR BATT → FLCS RLY 점등 → FLCS PWR TEST 홀드(PWR 4개·TO FLCS·PMG) → 해제 → MAIN PWR → EPU GEN/PMG 소등 → UHF 백업 교신 → 파킹브레이크 UP | J31: 부분적용 | L31: 2-7~2-8
A32: ☐ | B32: P2 | C32: 전원 인가 · 시동 전 | D32: Dash-1 | E32: W-08 | F32: 저온기상 운용 — 엔진 시동 전 | G32: Cold Weather Operation - Before Starting Engine | H32: 외기온 7°C(45°F) 이하이고 가시 습기(안개/비/눈)가 있는 조건에서 엔진 시동 준비 시 | I32: MAIN PWR → 캐노피 DOWN & CANOPY 등 소등 → (습기+7°C 이하) ANTI ICE ON → JFS 시동 | J32: 부분적용 | L32: 7-5
A33: ☐ | B33: P2 | C33: 전원 인가 · 시동 전 | D33: Dash-34 | E33: MP-20 | F33: 설계 시점(Design Eye)에 대한 좌석 조정 절차 | G33: Seat Adjustment for Design Eye Procedures | H33: 조종석 진입 후 스트랩인 및 항공기 전원(배터리/외부전원) 인가 직후, HUD 켜진 상태 | I33: HUD TEST ON → Seat Adjust 상하 조정(HUD 전체 가시) → HUD TEST OFF | J33: 부분적용 | L33: 1-311
A34: ■ P3 엔진 시동 · 항전 전원 (Engine Start / Avionics Power) — JFS 시동, 발전기, 항전 전원 인가.
A35: ☐ | B35: P3 | C35: 엔진 시동 · 항전 전원 | D35: Dash-1 | E35: N-10 | F35: 엔진 시동 - PW-229 | G35: Starting Engine PW-229 | H35: MAIN PWR 인가 및 시동 전 점검 완료 후 | I35: 해당 없음 — N-11(GE-129) 사용 | J35: 미구현 | L35: 2-8~2-9
A36: ☐ | B36: P3 | C36: 엔진 시동 · 항전 전원 | D36: Dash-1 | E36: N-11 | F36: 엔진 시동 - GE-129 | G36: Starting Engine GE-129 | H36: MAIN PWR 인가·EPU 등 소등 확인 후, 파킹브레이크 설정 상태 | I36: ENG FEED/AIR SOURCE NORM·스로틀 OFF → JFS START2 → JFS RUN 점등 → 20~25% RPM 스로틀 IDLE → SEC 소등(20%) → ENGINE 소등(60%) → JFS OFF(55%) → HYD/OIL 소등 → FF 700–1700/OIL 15+/NOZ 94+/RPM 62–80/FTIT ≤650/HYD 2850–3250 | J36: 적용 | L36: 2-9~2-11
A37: ☐ | B37: P3 | C37: 엔진 시동 · 항전 전원 | D37: Dash-1 | E37: N-29 | F37: 신속대응태세(Quick Response) 항공기 절차 | G37: Aircraft On Quick Response Status | H37: 스크램블 명령 수신, 사전 준비(N-28) 완료된 기체 탑승 시 | I37: BATT·FLCS RLY → MAIN PWR → JFS START2·IDLE → 캐노피 DOWN → 계기 → SNSR PWR → AVIONICS PWR → INS STOR HDG → FLCS BIT → MFD/SMS/HUD·C&I UFC → INS NAV → EPU GEN/PMG 소등 | J37: 부분적용 | L37: 2-30~2-31
A38: ☐ | B38: P3 | C38: 엔진 시동 · 항전 전원 | D38: Dash-1 | E38: W-09 | F38: 저온기상 운용 — 엔진 시동 | G38: Cold Weather Operation - Starting Engine | H38: 기체가 -29°C(-20°F)/-40°C 이하에서 1시간 이상 콜드소크된 상태에서 시동 시도 시 | I38: (미구현) 콜드소크 JFS 시동 제한 — DCS는 온도 무관 정상 시동 | J38: 미구현 | L38: 7-5
A39: ■ P4 INS 정렬 · 항법 초기화 (INS Alignment / Nav Init) — INS NORM/STOR HDG 정렬, DTE 로드, 시스템 시간, 항법 초기값.
A40: ☐ | B40: P4 | C40: INS 정렬 · 항법 초기화 | D40: Dash-34 | E40: MP-03 | F40: RLG INU 정렬 절차(그림 1-194) — 일반 자이로컴퍼스 정렬 | G40: RLG INU Alignment Procedures (Figure 1-194) - Normal Gyrocompass Alignment | H40: 엔진 시동 및 MMC/UFC 전원 인가 직후(정렬 시작 후 2분 이내 좌표 입력 필요) | I40: INS ALIGN NORM → DED INS 페이지 LAT ENTR/LNG ENTR(2분 내) → 상태 10 RDY 점멸 대기(약 8분) → INS NAV → 이륙 전 NAV 재확인 | J40: 적용 | L40: 1-276 ~ 1-277
A41: ☐ | B41: P4 | C41: INS 정렬 · 항법 초기화 | D41: Dash-34 | E41: MP-05 | F41: 강화 중단 정렬(EIA) 절차 | G41: Enhanced Interrupted Alignment (EIA) Procedures | H41: GPS 미보조 임무에서 8분 일반 정렬 완료(상태 10, RDY 점멸) 후 이륙 전 시간 여유가 있을 때 | I41: (미구현) 일반 정렬 10 RDY → INS NAV 로 대체 | J41: 미구현 | L41: 1-279
...

Sheet 단계별 집계
A1: 코드 | B1: 단계명 | C1: Dash-1 절차 수 | D1: Dash-34 절차 수 | E1: 합계 | F1: 적용 | G1: 부분적용 | H1: 미구현
A2: P0 | B2: 임무계획 / DTC 준비 | C2: =COUNTIFS('통합 체크리스트'!B:B,"P0",'통합 체크리스트'!D:D,"Dash-1") -> 2 | D2: =COUNTIFS('통합 체크리스트'!B:B,"P0",'통합 체크리스트'!D:D,"Dash-34") -> 2 | E2: =C2+D2 -> 4 | F2: =COUNTIFS('통합 체크리스트'!B:B,"P0",'통합 체크리스트'!J:J,"적용") -> 0 | G2: =COUNTIFS('통합 체크리스트'!B:B,"P0",'통합 체크리스트'!J:J,"부분적용") -> 4 | H2: =COUNTIFS('통합 체크리스트'!B:B,"P0",'통합 체크리스트'!J:J,"미구현") -> 0
A3: P1 | B3: 조종석 진입 전 · 외부점검 | C3: =COUNTIFS('통합 체크리스트'!B:B,"P1",'통합 체크리스트'!D:D,"Dash-1") -> 3 | D3: =COUNTIFS('통합 체크리스트'!B:B,"P1",'통합 체크리스트'!D:D,"Dash-34") -> 11 | E3: =C3+D3 -> 14 | F3: =COUNTIFS('통합 체크리스트'!B:B,"P1",'통합 체크리스트'!J:J,"적용") -> 0 | G3: =COUNTIFS('통합 체크리스트'!B:B,"P1",'통합 체크리스트'!J:J,"부분적용") -> 1 | H3: =COUNTIFS('통합 체크리스트'!B:B,"P1",'통합 체크리스트'!J:J,"미구현") -> 13
A4: P2 | B4: 전원 인가 · 시동 전 | C4: =COUNTIFS('통합 체크리스트'!B:B,"P2",'통합 체크리스트'!D:D,"Dash-1") -> 10 | D4: =COUNTIFS('통합 체크리스트'!B:B,"P2",'통합 체크리스트'!D:D,"Dash-34") -> 1 | E4: =C4+D4 -> 11 | F4: =COUNTIFS('통합 체크리스트'!B:B,"P2",'통합 체크리스트'!J:J,"적용") -> 2 | G4: =COUNTIFS('통합 체크리스트'!B:B,"P2",'통합 체크리스트'!J:J,"부분적용") -> 9 | H4: =COUNTIFS('통합 체크리스트'!B:B,"P2",'통합 체크리스트'!J:J,"미구현") -> 0
A5: P3 | B5: 엔진 시동 · 항전 전원 | C5: =COUNTIFS('통합 체크리스트'!B:B,"P3",'통합 체크리스트'!D:D,"Dash-1") -> 4 | D5: =COUNTIFS('통합 체크리스트'!B:B,"P3",'통합 체크리스트'!D:D,"Dash-34") -> 0 | E5: =C5+D5 -> 4 | F5: =COUNTIFS('통합 체크리스트'!B:B,"P3",'통합 체크리스트'!J:J,"적용") -> 1 | G5: =COUNTIFS('통합 체크리스트'!B:B,"P3",'통합 체크리스트'!J:J,"부분적용") -> 1 | H5: =COUNTIFS('통합 체크리스트'!B:B,"P3",'통합 체크리스트'!J:J,"미구현") -> 2
A6: P4 | B6: INS 정렬 · 항법 초기화 | C6: =COUNTIFS('통합 체크리스트'!B:B,"P4",'통합 체크리스트'!D:D,"Dash-1") -> 0 | D6: =COUNTIFS('통합 체크리스트'!B:B,"P4",'통합 체크리스트'!D:D,"Dash-34") -> 4 | E6: =C6+D6 -> 4 | F6: =COUNTIFS('통합 체크리스트'!B:B,"P4",'통합 체크리스트'!J:J,"적용") -> 1 | G6: =COUNTIFS('통합 체크리스트'!B:B,"P4",'통합 체크리스트'!J:J,"부분적용") -> 2 | H6: =COUNTIFS('통합 체크리스트'!B:B,"P4",'통합 체크리스트'!J:J,"미구현") -> 1
A7: P5 | B7: 시동 후 점검 · 무장/센서 셋업 · BIT | C7: =COUNTIFS('통합 체크리스트'!B:B,"P5",'통합 체크리스트'!D:D,"Dash-1") -> 2 | D7: =COUNTIFS('통합 체크리스트'!B:B,"P5",'통합 체크리스트'!D:D,"Dash-34") -> 18 | E7: =C7+D7 -> 20 | F7: =COUNTIFS('통합 체크리스트'!B:B,"P5",'통합 체크리스트'!J:J,"적용") -> 5 | G7: =COUNTIFS('통합 체크리스트'!B:B,"P5",'통합 체크리스트'!J:J,"부분적용") -> 9 | H7: =COUNTIFS('통합 체크리스트'!B:B,"P5",'통합 체크리스트'!J:J,"미구현") -> 6
A8: P6 | B8: 택시 · 이륙 전 점검 | C8: =COUNTIFS('통합 체크리스트'!B:B,"P6",'통합 체크리스트'!D:D,"Dash-1") -> 7 | D8: =COUNTIFS('통합 체크리스트'!B:B,"P6",'통합 체크리스트'!D:D,"Dash-34") -> 5 | E8: =C8+D8 -> 12 | F8: =COUNTIFS('통합 체크리스트'!B:B,"P6",'통합 체크리스트'!J:J,"적용") -> 1 | G8: =COUNTIFS('통합 체크리스트'!B:B,"P6",'통합 체크리스트'!J:J,"부분적용") -> 7 | H8: =COUNTIFS('통합 체크리스트'!B:B,"P6",'통합 체크리스트'!J:J,"미구현") -> 4
A9: P7 | B9: 이륙 · 상승 | C9: =COUNTIFS('통합 체크리스트'!B:B,"P7",'통합 체크리스트'!D:D,"Dash-1") -> 5 | D9: =COUNTIFS('통합 체크리스트'!B:B,"P7",'통합 체크리스트'!D:D,"Dash-34") -> 1 | E9: =C9+D9 -> 6 | F9: =COUNTIFS('통합 체크리스트'!B:B,"P7",'통합 체크리스트'!J:J,"적용") -> 1 | G9: =COUNTIFS('통합 체크리스트'!B:B,"P7",'통합 체크리스트'!J:J,"부분적용") -> 4 | H9: =COUNTIFS('통합 체크리스트'!B:B,"P7",'통합 체크리스트'!J:J,"미구현") -> 1
A10: P8 | B10: 순항 · 항법 · 연료관리 | C10: =COUNTIFS('통합 체크리스트'!B:B,"P8",'통합 체크리스트'!D:D,"Dash-1") -> 6 | D10: =COUNTIFS('통합 체크리스트'!B:B,"P8",'통합 체크리스트'!D:D,"Dash-34") -> 17 | E10: =C10+D10 -> 23 | F10: =COUNTIFS('통합 체크리스트'!B:B,"P8",'통합 체크리스트'!J:J,"적용") -> 13 | G10: =COUNTIFS('통합 체크리스트'!B:B,"P8",'통합 체크리스트'!J:J,"부분적용") -> 5 | H10: =COUNTIFS('통합 체크리스트'!B:B,"P8",'통합 체크리스트'!J:J,"미구현") -> 5
A11: P9 | B11: 공중급유 | C11: =COUNTIFS('통합 체크리스트'!B:B,"P9",'통합 체크리스트'!D:D,"Dash-1") -> 57 | D11: =COUNTIFS('통합 체크리스트'!B:B,"P9",'통합 체크리스트'!D:D,"Dash-34") -> 0 | E11: =C11+D11 -> 57 | F11: =COUNTIFS('통합 체크리스트'!B:B,"P9",'통합 체크리스트'!J:J,"적용") -> 10 | G11: =COUNTIFS('통합 체크리스트'!B:B,"P9",'통합 체크리스트'!J:J,"부분적용") -> 37 | H11: =COUNTIFS('통합 체크리스트'!B:B,"P9",'통합 체크리스트'!J:J,"미구현") -> 10
A12: P10 | B12: 전투진입 준비 (Fence-In) | C12: =COUNTIFS('통합 체크리스트'!B:B,"P10",'통합 체크리스트'!D:D,"Dash-1") -> 0 | D12: =COUNTIFS('통합 체크리스트'!B:B,"P10",'통합 체크리스트'!D:D,"Dash-34") -> 5 | E12: =C12+D12 -> 5 | F12: =COUNTIFS('통합 체크리스트'!B:B,"P10",'통합 체크리스트'!J:J,"적용") -> 1 | G12: =COUNTIFS('통합 체크리스트'!B:B,"P10",'통합 체크리스트'!J:J,"부분적용") -> 2 | H12: =COUNTIFS('통합 체크리스트'!B:B,"P10",'통합 체크리스트'!J:J,"미구현") -> 2
A13: P11 | B13: 공대공 교전 | C13: =COUNTIFS('통합 체크리스트'!B:B,"P11",'통합 체크리스트'!D:D,"Dash-1") -> 0 | D13: =COUNTIFS('통합 체크리스트'!B:B,"P11",'통합 체크리스트'!D:D,"Dash-34") -> 6 | E13: =C13+D13 -> 6 | F13: =COUNTIFS('통합 체크리스트'!B:B,"P11",'통합 체크리스트'!J:J,"적용") -> 3 | G13: =COUNTIFS('통합 체크리스트'!B:B,"P11",'통합 체크리스트'!J:J,"부분적용") -> 2 | H13: =COUNTIFS('통합 체크리스트'!B:B,"P11",'통합 체크리스트'!J:J,"미구현") -> 1
A14: P12 | B14: 공대지 공격 | C14: =COUNTIFS('통합 체크리스트'!B:B,"P12",'통합 체크리스트'!D:D,"Dash-1") -> 0 | D14: =COUNTIFS('통합 체크리스트'!B:B,"P12",'통합 체크리스트'!D:D,"Dash-34") -> 16 | E14: =C14+D14 -> 16 | F14: =COUNTIFS('통합 체크리스트'!B:B,"P12",'통합 체크리스트'!J:J,"적용") -> 11 | G14: =COUNTIFS('통합 체크리스트'!B:B,"P12",'통합 체크리스트'!J:J,"부분적용") -> 2 | H14: =COUNTIFS('통합 체크리스트'!B:B,"P12",'통합 체크리스트'!J:J,"미구현") -> 3
A15: P13 | B15: 방어 · 회피 | C15: =COUNTIFS('통합 체크리스트'!B:B,"P13",'통합 체크리스트'!D:D,"Dash-1") -> 0 | D15: =COUNTIFS('통합 체크리스트'!B:B,"P13",'통합 체크리스트'!D:D,"Dash-34") -> 2 | E15: =C15+D15 -> 2 | F15: =COUNTIFS('통합 체크리스트'!B:B,"P13",'통합 체크리스트'!J:J,"적용") -> 2 | G15: =COUNTIFS('통합 체크리스트'!B:B,"P13",'통합 체크리스트'!J:J,"부분적용") -> 0 | H15: =COUNTIFS('통합 체크리스트'!B:B,"P13",'통합 체크리스트'!J:J,"미구현") -> 0
A16: P14 | B16: 이탈 · 복귀 (Fence-Out / RTB) | C16: =COUNTIFS('통합 체크리스트'!B:B,"P14",'통합 체크리스트'!D:D,"Dash-1") -> 0 | D16: =COUNTIFS('통합 체크리스트'!B:B,"P14",'통합 체크리스트'!D:D,"Dash-34") -> 4 | E16: =C16+D16 -> 4 | F16: =COUNTIFS('통합 체크리스트'!B:B,"P14",'통합 체크리스트'!J:J,"적용") -> 3 | G16: =COUNTIFS('통합 체크리스트'!B:B,"P14",'통합 체크리스트'!J:J,"부분적용") -> 0 | H16: =COUNTIFS('통합 체크리스트'!B:B,"P14",'통합 체크리스트'!J:J,"미구현") -> 1
A17: P15 | B17: 접근 · 착륙 | C17: =COUNTIFS('통합 체크리스트'!B:B,"P15",'통합 체크리스트'!D:D,"Dash-1") -> 11 | D17: =COUNTIFS('통합 체크리스트'!B:B,"P15",'통합 체크리스트'!D:D,"Dash-34") -> 0 | E17: =C17+D17 -> 11 | F17: =COUNTIFS('통합 체크리스트'!B:B,"P15",'통합 체크리스트'!J:J,"적용") -> 6 | G17: =COUNTIFS('통합 체크리스트'!B:B,"P15",'통합 체크리스트'!J:J,"부분적용") -> 5 | H17: =COUNTIFS('통합 체크리스트'!B:B,"P15",'통합 체크리스트'!J:J,"미구현") -> 0
A18: P16 | B18: 착륙 후 · 엔진 정지 | C18: =COUNTIFS('통합 체크리스트'!B:B,"P16",'통합 체크리스트'!D:D,"Dash-1") -> 4 | D18: =COUNTIFS('통합 체크리스트'!B:B,"P16",'통합 체크리스트'!D:D,"Dash-34") -> 2 | E18: =C18+D18 -> 6 | F18: =COUNTIFS('통합 체크리스트'!B:B,"P16",'통합 체크리스트'!J:J,"적용") -> 1 | G18: =COUNTIFS('통합 체크리스트'!B:B,"P16",'통합 체크리스트'!J:J,"부분적용") -> 4 | H18: =COUNTIFS('통합 체크리스트'!B:B,"P16",'통합 체크리스트'!J:J,"미구현") -> 1
A19: PX | B19: 비정상 · 비상 (발생 시) | C19: =COUNTIFS('통합 체크리스트'!B:B,"PX",'통합 체크리스트'!D:D,"Dash-1") -> 129 | D19: =COUNTIFS('통합 체크리스트'!B:B,"PX",'통합 체크리스트'!D:D,"Dash-34") -> 25 | E19: =C19+D19 -> 154 | F19: =COUNTIFS('통합 체크리스트'!B:B,"PX",'통합 체크리스트'!J:J,"적용") -> 21 | G19: =COUNTIFS('통합 체크리스트'!B:B,"PX",'통합 체크리스트'!J:J,"부분적용") -> 97 | H19: =COUNTIFS('통합 체크리스트'!B:B,"PX",'통합 체크리스트'!J:J,"미구현") -> 36
A20: PA | B20: 상시 · 필요 시 | C20: =COUNTIFS('통합 체크리스트'!B:B,"PA",'통합 체크리스트'!D:D,"Dash-1") -> 8 | D20: =COUNTIFS('통합 체크리스트'!B:B,"PA",'통합 체크리스트'!D:D,"Dash-34") -> 9 | E20: =C20+D20 -> 17 | F20: =COUNTIFS('통합 체크리스트'!B:B,"PA",'통합 체크리스트'!J:J,"적용") -> 3 | G20: =COUNTIFS('통합 체크리스트'!B:B,"PA",'통합 체크리스트'!J:J,"부분적용") -> 7 | H20: =COUNTIFS('통합 체크리스트'!B:B,"PA",'통합 체크리스트'!J:J,"미구현") -> 7
B21: 합계 | C21: =SUM(C2:C20) -> 248 | D21: =SUM(D2:D20) -> 128 | E21: =SUM(E2:E20) -> 376 | F21: =SUM(F2:F20) -> 85 | G21: =SUM(G2:G20) -> 198 | H21: =SUM(H2:H20) -> 93
A23: 설명
A24: Dash-1(비행 매뉴얼 T.O. GR1F-16CJ-1)과 Dash-34(항전·무장 T.O. GR1F-16CJ-34-1-1)의 절차를 같은 임무단계 코드로 합친 체크리스트. 각 절차의 상세(원문 단계, DCS 조작 절차, Chuck's Guide 참조)는 각 정리본 파일의 '절차 마스터' 시트를 ID로 찾아보세요. BOLDFACE ●는 비상 암기 항목 포함 절차.
